Workbook

Sheet Executive_Summary
A1: Granite Ridge Apartment Partners - October 1 Renewal Batch Underwriting Review
A2: Program GRP-HAB-MW Multi-Family | Prepared for the Chief Underwriting Officer | Routing rules: granite_ridge_routing_notes.txt (desk ref GRP-RNW-2025-10)
A4: Routing parameters (from granite_ridge_routing_notes.txt)
A5: Batch effective date | C5: 45931 | D5: Section 5
A6: Inspection grace window (days before effective date) | C6: 30 | D6: Section 5
A7: Attritional loss basis | C7: paid + reserved, cat_code blank only | D7: Sections 3 and 9
A8: Loss ratio Decline threshold (>=) | C8: 0.7 | D8: Section 3
A9: Loss ratio Refer threshold (>=) | C9: 0.45 | D9: Section 3
A10: Single-location incurred Refer threshold (>=) | C10: 250000 | D10: Section 3
A11: Unit count variance Refer threshold (>) | C11: 0.05 | D11: Section 4
A12: TIV variance Refer threshold (>) | C12: 0.03 | D12: Section 4
A14: Disposition counts
A15: Disposition | C15: Accounts | D15: % of batch | E15: Account IDs
A16: Quote | C16: =COUNTIF(Account_Routing!$AB$2:$AB$37,A16) | D16: =C16/$C$20 | E16: See Account_Routing (25 accounts)
A17: Refer | C17: =COUNTIF(Account_Routing!$AB$2:$AB$37,A17) | D17: =C17/$C$20 | E17: GR-2007, GR-2053, GR-2065, GR-2068, GR-2074, GR-2089, GR-2092, GR-2113, GR-2162
A18: Decline | C18: =COUNTIF(Account_Routing!$AB$2:$AB$37,A18) | D18: =C18/$C$20 | E18: GR-2195
A19: Ask Broker | C19: =COUNTIF(Account_Routing!$AB$2:$AB$37,A19) | D19: =C19/$C$20 | E19: GR-2033
A20: Total accounts reviewed | C20: =COUNTA(Account_Routing!$A$2:$A$37)
A21: Check: dispositions sum to total | C21: =IF(SUM(C16:C19)=C20,"OK","ERROR")
A22: Check: total equals 36 accounts in export | C22: =IF(C20=36,"OK","ERROR")
A24: Exception counts (reconcile to Location_Exceptions / Account_Routing)
A25: Accounts with any location-level exception (subsidized, inspection, pool, vacancy) | C25: =SUMPRODUCT(--((Account_Routing!$N$2:$N$37+Account_Routing!$P$2:$P$37+Account_Routing!$Q$2:$Q$37+Account_Routing!$R$2:$R$37)>0))
A26: Subsidized-housing locations (subsidized_unit_count > 0) | C26: =COUNTIF(Src_Locations!$G$2:$G$76,">0")
A27: Accounts with subsidized locations | C27: =COUNTIF(Account_Routing!$N$2:$N$37,">0")
A28: Locations with life-safety inspection lapse (>30 days before 10/1/2025) | C28: =SUM(Src_Locations!$P$2:$P$76)
A29: Locations with pool_liability_flag = pending_fence_po | C29: =COUNTIF(Src_Locations!$L$2:$L$76,"pending_fence_po")
A30: Locations with vacancy_flag = Y | C30: =COUNTIF(Src_Locations!$I$2:$I$76,"Y")
A31: of which broker_confirmation = no (Ask Broker) | C31: =SUM(Src_Locations!$R$2:$R$76)
A32: Accounts failing unit count reconciliation (>5%) | C32: =COUNTIF(Account_Routing!$I$2:$I$37,">"&$C$11)
A33: Accounts failing TIV reconciliation (>3%) | C33: =COUNTIF(Account_Routing!$L$2:$L$37,">"&$C$12)
A34: Accounts where list loss ratio differs from recomputed by more than 5 points | C34: =COUNTIF(Loss_Reconciliation!$K$2:$K$37,"Yes")
A35: Accounts with recomputed LR >= 45% (Refer or Decline band) | C35: =COUNTIF(Account_Routing!$V$2:$V$37,">="&$C$9)
A36: Accounts with a single location incurred >= $250,000 | C36: =COUNTIF(Account_Routing!$W$2:$W$37,">="&$C$10)
A37: Campus Edge (Section 10) accounts | C37: =SUM(Account_Routing!$X$2:$X$37)
A38: Accounts marked renewal_ready_flag = Y on the list but not routed Quote (Section 8) | C38: =COUNTIFS(Account_Routing!$F$2:$F$37,"Y",Account_Routing!$AB$2:$AB$37,"<>Quote")
A40: Headline for the CUO
A41: The October batch has 36 accounts, all routed. Twenty-five are cleared to quote; nine require underwriter review (Refer); GR-2195 (Humboldt Yard) hits a 292.3% recomputed loss ratio and is declined; GR-2033 (Lincolnwood Place) needs broker vacancy confirmation before we can proceed. The account list flagged every account renewal-ready, but that is informational per Section 8. Judgment calls on Campus Edge (Section 10), GR-2047 vacancy, and GR-2071 cat exclusion are documented on Decision_Notes.

Sheet Account_Routing
A1: account_id | B1: named_insured | C1: state | D1: expiring_premium | E1: prior_disposition (list) | F1: renewal_ready_flag (list) | G1: list_unit_count | H1: schedule_unit_sum | I1: unit_variance_% | J1: list_account_tiv | K1: schedule_tiv_sum | L1: tiv_variance_% | M1: location_count | N1: subsidized_locations (units>0) | O1: list_subsidized_flag | P1: life_safety_lapse_locations | Q1: pool_pending_fence_po_locations | R1: vacancy_Y_locations | S1: vacancy_Y_broker_not_yes | T1: occupancy_pct (list) | U1: list_loss_ratio | V1: recomputed_attritional_LR | W1: max_single_location_incurred | X1: student_housing_flag (Sec 10) | Y1: Decline trigger | Z1: Ask Broker trigger | AA1: Refer trigger count | AB1: DISPOSITION | AC1: rule_section(s) applied | AD1: rationale (rule section + source file)
A2: GR-2001 | B2: Ashland Court Apts LP | C2: IL | D2: 55299.51 | E2: Quoted | F2: Y | G2: 183 | H2: =SUMIFS(Src_Locations!$F$2:$F$76,Src_Locations!$B$2:$B$76,A2) | I2: =ABS(G2-H2)/G2 | J2: 11870554 | K2: =SUMIFS(Src_Locations!$E$2:$E$76,Src_Locations!$B$2:$B$76,A2) | L2: =ABS(J2-K2)/J2 | M2: =COUNTIF(Src_Locations!$B$2:$B$76,A2) | N2: =COUNTIFS(Src_Locations!$B$2:$B$76,A2,Src_Locations!$G$2:$G$76,">0") | O2: N | P2: =SUMIFS(Src_Locations!$P$2:$P$76,Src_Locations!$B$2:$B$76,A2) | Q2: =COUNTIFS(Src_Locations!$B$2:$B$76,A2,Src_Locations!$L$2:$L$76,"pending_fence_po") | R2: =COUNTIFS(Src_Locations!$B$2:$B$76,A2,Src_Locations!$I$2:$I$76,"Y") | S2: =SUMIFS(Src_Locations!$R$2:$R$76,Src_Locations!$B$2:$B$76,A2) | T2: 0.953 | U2: 0.259 | V2: =SUMIFS(Src_LossRun!$J$2:$J$43,Src_LossRun!$C$2:$C$43,A2)/D2 | W2: =_xlfn.MAXIFS(Src_Locations!$Q$2:$Q$76,Src_Locations!$B$2:$B$76,A2) | X2: =IF(B2="Campus Edge Housing Co.",1,0) | Y2: =IF(V2>=Executive_Summary!$C$8,1,0) | Z2: =IF(S2>0,1,0) | AA2: =(V2>=Executive_Summary!$C$9)+(W2>=Executive_Summary!$C$10)+(I2>Executive_Summary!$C$11)+(L2>Executive_Summary!$C$12)+(P2>0)+(Q2>0)+(N2>0)+(X2=1) | AB2: =IF(Y2=1,"Decline",IF(Z2=1,"Ask Broker",IF(AA2>0,"Refer","Quote"))) | AC2: Sec 3-6 | AD2: Attritional LR 11.3%. Units/TIV within tolerance; inspections within grace window; no subsidized-housing, vacancy, or pool triggers. Quote per granite_ridge_routing_notes.txt.
A3: GR-2004 | B3: Berwyn Arms LLC | C3: MN | D3: 75553.66 | E3: Quoted | F3: Y | G3: 67 | H3: =SUMIFS(Src_Locations!$F$2:$F$76,Src_Locations!$B$2:$B$76,A3) | I3: =ABS(G3-H3)/G3 | J3: 10119822 | K3: =SUMIFS(Src_Locations!$E$2:$E$76,Src_Locations!$B$2:$B$76,A3) | L3: =ABS(J3-K3)/J3 | M3: =COUNTIF(Src_Locations!$B$2:$B$76,A3) | N3: =COUNTIFS(Src_Locations!$B$2:$B$76,A3,Src_Locations!$G$2:$G$76,">0") | O3: N | P3: =SUMIFS(Src_Locations!$P$2:$P$76,Src_Locations!$B$2:$B$76,A3) | Q3: =COUNTIFS(Src_Locations!$B$2:$B$76,A3,Src_Locations!$L$2:$L$76,"pending_fence_po") | R3: =COUNTIFS(Src_Locations!$B$2:$B$76,A3,Src_Locations!$I$2:$I$76,"Y") | S3: =SUMIFS(Src_Locations!$R$2:$R$76,Src_Locations!$B$2:$B$76,A3) | T3: 0.961 | U3: 0.128 | V3: =SUMIFS(Src_LossRun!$J$2:$J$43,Src_LossRun!$C$2:$C$43,A3)/D3 | W3: =_xlfn.MAXIFS(Src_Locations!$Q$2:$Q$76,Src_Locations!$B$2:$B$76,A3) | X3: =IF(B3="Campus Edge Housing Co.",1,0) | Y3: =IF(V3>=Executive_Summary!$C$8,1,0) | Z3: =IF(S3>0,1,0) | AA3: =(V3>=Executive_Summary!$C$9)+(W3>=Executive_Summary!$C$10)+(I3>Executive_Summary!$C$11)+(L3>Executive_Summary!$C$12)+(P3>0)+(Q3>0)+(N3>0)+(X3=1) | AB3: =IF(Y3=1,"Decline",IF(Z3=1,"Ask Broker",IF(AA3>0,"Refer","Quote"))) | AC3: Sec 3-6 | AD3: Attritional LR 26.4%. Units/TIV within tolerance; inspections within grace window; no subsidized-housing, vacancy, or pool triggers. Quote per granite_ridge_routing_notes.txt.
A4: GR-2007 | B4: Campus Edge Housing Co. | C4: IN | D4: 67915.72 | E4: Quoted | F4: Y | G4: 97 | H4: =SUMIFS(Src_Locations!$F$2:$F$76,Src_Locations!$B$2:$B$76,A4) | I4: =ABS(G4-H4)/G4 | J4: 10381367 | K4: =SUMIFS(Src_Locations!$E$2:$E$76,Src_Locations!$B$2:$B$76,A4) | L4: =ABS(J4-K4)/J4 | M4: =COUNTIF(Src_Locations!$B$2:$B$76,A4) | N4: =COUNTIFS(Src_Locations!$B$2:$B$76,A4,Src_Locations!$G$2:$G$76,">0") | O4: N | P4: =SUMIFS(Src_Locations!$P$2:$P$76,Src_Locations!$B$2:$B$76,A4) | Q4: =COUNTIFS(Src_Locations!$B$2:$B$76,A4,Src_Locations!$L$2:$L$76,"pending_fence_po") | R4: =COUNTIFS(Src_Locations!$B$2:$B$76,A4,Src_Locations!$I$2:$I$76,"Y") | S4: =SUMIFS(Src_Locations!$R$2:$R$76,Src_Locations!$B$2:$B$76,A4) | T4: 0.952 | U4: 0.179 | V4: =SUMIFS(Src_LossRun!$J$2:$J$43,Src_LossRun!$C$2:$C$43,A4)/D4 | W4: =_xlfn.MAXIFS(Src_Locations!$Q$2:$Q$76,Src_Locations!$B$2:$B$76,A4) | X4: =IF(B4="Campus Edge Housing Co.",1,0) | Y4: =IF(V4>=Executive_Summary!$C$8,1,0) | Z4: =IF(S4>0,1,0) | AA4: =(V4>=Executive_Summary!$C$9)+(W4>=Executive_Summary!$C$10)+(I4>Executive_Summary!$C$11)+(L4>Executive_Summary!$C$12)+(P4>0)+(Q4>0)+(N4>0)+(X4=1) | AB4: =IF(Y4=1,"Decline",IF(Z4=1,"Ask Broker",IF(AA4>0,"Refer","Quote"))) | AC4: Sec 10 | AD4: Section 10 per granite_ridge_routing_notes.txt: Campus Edge student-housing insured; GRP-APPETITE review must be submitted before bind, no CUO clearance memo in file package (judgment: treated as mandatory pre-bind review = Refer per Section 2). Source: granite_ridge_renewal_accounts.csv, granite_ridge_routing_notes.txt.
A5: GR-2010 | B5: Damen Square Residences | C5: IA | D5: 87072.61 | E5: Quoted | F5: Y | G5: 128 | H5: =SUMIFS(Src_Locations!$F$2:$F$76,Src_Locations!$B$2:$B$76,A5) | I5: =ABS(G5-H5)/G5 | J5: 15930329 | K5: =SUMIFS(Src_Locations!$E$2:$E$76,Src_Locations!$B$2:$B$76,A5) | L5: =ABS(J5-K5)/J5 | M5: =COUNTIF(Src_Locations!$B$2:$B$76,A5) | N5: =COUNTIFS(Src_Locations!$B$2:$B$76,A5,Src_Locations!$G$2:$G$76,">0") | O5: N | P5: =SUMIFS(Src_Locations!$P$2:$P$76,Src_Locations!$B$2:$B$76,A5) | Q5: =COUNTIFS(Src_Locations!$B$2:$B$76,A5,Src_Locations!$L$2:$L$76,"pending_fence_po") | R5: =COUNTIFS(Src_Locations!$B$2:$B$76,A5,Src_Locations!$I$2:$I$76,"Y") | S5: =SUMIFS(Src_Locations!$R$2:$R$76,Src_Locations!$B$2:$B$76,A5) | T5: 0.912 | U5: 0.171 | V5: =SUMIFS(Src_LossRun!$J$2:$J$43,Src_LossRun!$C$2:$C$43,A5)/D5 | W5: =_xlfn.MAXIFS(Src_Locations!$Q$2:$Q$76,Src_Locations!$B$2:$B$76,A5) | X5: =IF(B5="Campus Edge Housing Co.",1,0) | Y5: =IF(V5>=Executive_Summary!$C$8,1,0) | Z5: =IF(S5>0,1,0) | AA5: =(V5>=Executive_Summary!$C$9)+(W5>=Executive_Summary!$C$10)+(I5>Executive_Summary!$C$11)+(L5>Executive_Summary!$C$12)+(P5>0)+(Q5>0)+(N5>0)+(X5=1) | AB5: =IF(Y5=1,"Decline",IF(Z5=1,"Ask Broker",IF(AA5>0,"Refer","Quote"))) | AC5: Sec 3-6 | AD5: Recomputed LR 6.1%, well under Section 3 thresholds. Location schedule reconciles within tolerance. Inspections current. Quote per granite_ridge_routing_notes.txt.
A6: GR-2013 | B6: Eastgate Manor LLC | C6: IL | D6: 55911.94 | E6: Quoted | F6: Y | G6: 163 | H6: =SUMIFS(Src_Locations!$F$2:$F$76,Src_Locations!$B$2:$B$76,A6) | I6: =ABS(G6-H6)/G6 | J6: 10882945 | K6: =SUMIFS(Src_Locations!$E$2:$E$76,Src_Locations!$B$2:$B$76,A6) | L6: =ABS(J6-K6)/J6 | M6: =COUNTIF(Src_Locations!$B$2:$B$76,A6) | N6: =COUNTIFS(Src_Locations!$B$2:$B$76,A6,Src_Locations!$G$2:$G$76,">0") | O6: N | P6: =SUMIFS(Src_Locations!$P$2:$P$76,Src_Locations!$B$2:$B$76,A6) | Q6: =COUNTIFS(Src_Locations!$B$2:$B$76,A6,Src_Locations!$L$2:$L$76,"pending_fence_po") | R6: =COUNTIFS(Src_Locations!$B$2:$B$76,A6,Src_Locations!$I$2:$I$76,"Y") | S6: =SUMIFS(Src_Locations!$R$2:$R$76,Src_Locations!$B$2:$B$76,A6) | T6: 0.924 | U6: 0.205 | V6: =SUMIFS(Src_LossRun!$J$2:$J$43,Src_LossRun!$C$2:$C$43,A6)/D6 | W6: =_xlfn.MAXIFS(Src_Locations!$Q$2:$Q$76,Src_Locations!$B$2:$B$76,A6) | X6: =IF(B6="Campus Edge Housing Co.",1,0) | Y6: =IF(V6>=Executive_Summary!$C$8,1,0) | Z6: =IF(S6>0,1,0) | AA6: =(V6>=Executive_Summary!$C$9)+(W6>=Executive_Summary!$C$10)+(I6>Executive_Summary!$C$11)+(L6>Executive_Summary!$C$12)+(P6>0)+(Q6>0)+(N6>0)+(X6=1) | AB6: =IF(Y6=1,"Decline",IF(Z6=1,"Ask Broker",IF(AA6>0,"Refer","Quote"))) | AC6: Sec 3-6 | AD6: Recomputed LR 22.2%, well under Section 3 thresholds. Location schedule reconciles within tolerance. Inspections current. Quote per granite_ridge_routing_notes.txt.
A7: GR-2016 | B7: Fairmount Village Apts | C7: IA | D7: 67173.6 | E7: Quoted | F7: Y | G7: 172 | H7: =SUMIFS(Src_Locations!$F$2:$F$76,Src_Locations!$B$2:$B$76,A7) | I7: =ABS(G7-H7)/G7 | J7: 14236352 | K7: =SUMIFS(Src_Locations!$E$2:$E$76,Src_Locations!$B$2:$B$76,A7) | L7: =ABS(J7-K7)/J7 | M7: =COUNTIF(Src_Locations!$B$2:$B$76,A7) | N7: =COUNTIFS(Src_Locations!$B$2:$B$76,A7,Src_Locations!$G$2:$G$76,">0") | O7: N | P7: =SUMIFS(Src_Locations!$P$2:$P$76,Src_Locations!$B$2:$B$76,A7) | Q7: =COUNTIFS(Src_Locations!$B$2:$B$76,A7,Src_Locations!$L$2:$L$76,"pending_fence_po") | R7: =COUNTIFS(Src_Locations!$B$2:$B$76,A7,Src_Locations!$I$2:$I$76,"Y") | S7: =SUMIFS(Src_Locations!$R$2:$R$76,Src_Locations!$B$2:$B$76,A7) | T7: 0.919 | U7: 0.302 | V7: =SUMIFS(Src_LossRun!$J$2:$J$43,Src_LossRun!$C$2:$C$43,A7)/D7 | W7: =_xlfn.MAXIFS(Src_Locations!$Q$2:$Q$76,Src_Locations!$B$2:$B$76,A7) | X7: =IF(B7="Campus Edge Housing Co.",1,0) | Y7: =IF(V7>=Executive_Summary!$C$8,1,0) | Z7: =IF(S7>0,1,0) | AA7: =(V7>=Executive_Summary!$C$9)+(W7>=Executive_Summary!$C$10)+(I7>Executive_Summary!$C$11)+(L7>Executive_Summary!$C$12)+(P7>0)+(Q7>0)+(N7>0)+(X7=1) | AB7: =IF(Y7=1,"Decline",IF(Z7=1,"Ask Broker",IF(AA7>0,"Refer","Quote"))) | AC7: Sec 3-6 | AD7: Attritional LR 18.1% (below 45% Refer band); units, TIV, inspections all clear; no subsidized units, vacancy, or pool hold. Quote per granite_ridge_routing_notes.txt.
A8: GR-2018 | B8: Glenwood Terrace LLC | C8: IA | D8: 54820 | E8: Quoted | F8: Y | G8: 112 | H8: =SUMIFS(Src_Locations!$F$2:$F$76,Src_Locations!$B$2:$B$76,A8) | I8: =ABS(G8-H8)/G8 | J8: 9340000 | K8: =SUMIFS(Src_Locations!$E$2:$E$76,Src_Locations!$B$2:$B$76,A8) | L8: =ABS(J8-K8)/J8 | M8: =COUNTIF(Src_Locations!$B$2:$B$76,A8) | N8: =COUNTIFS(Src_Locations!$B$2:$B$76,A8,Src_Locations!$G$2:$G$76,">0") | O8: N | P8: =SUMIFS(Src_Locations!$P$2:$P$76,Src_Locations!$B$2:$B$76,A8) | Q8: =COUNTIFS(Src_Locations!$B$2:$B$76,A8,Src_Locations!$L$2:$L$76,"pending_fence_po") | R8: =COUNTIFS(Src_Locations!$B$2:$B$76,A8,Src_Locations!$I$2:$I$76,"Y") | S8: =SUMIFS(Src_Locations!$R$2:$R$76,Src_Locations!$B$2:$B$76,A8) | T8: 0.972 | U8: 0.186 | V8: =SUMIFS(Src_LossRun!$J$2:$J$43,Src_LossRun!$C$2:$C$43,A8)/D8 | W8: =_xlfn.MAXIFS(Src_Locations!$Q$2:$Q$76,Src_Locations!$B$2:$B$76,A8) | X8: =IF(B8="Campus Edge Housing Co.",1,0) | Y8: =IF(V8>=Executive_Summary!$C$8,1,0) | Z8: =IF(S8>0,1,0) | AA8: =(V8>=Executive_Summary!$C$9)+(W8>=Executive_Summary!$C$10)+(I8>Executive_Summary!$C$11)+(L8>Executive_Summary!$C$12)+(P8>0)+(Q8>0)+(N8>0)+(X8=1) | AB8: =IF(Y8=1,"Decline",IF(Z8=1,"Ask Broker",IF(AA8>0,"Refer","Quote"))) | AC8: Sec 3-6 | AD8: Recomputed LR 9.8%, well under Section 3 thresholds. Location schedule reconciles within tolerance. Inspections current. Quote per granite_ridge_routing_notes.txt.
A9: GR-2021 | B9: Halsted Walkup Partners | C9: OH | D9: 69181.2 | E9: Quoted | F9: Y | G9: 109 | H9: =SUMIFS(Src_Locations!$F$2:$F$76,Src_Locations!$B$2:$B$76,A9) | I9: =ABS(G9-H9)/G9 | J9: 8365947 | K9: =SUMIFS(Src_Locations!$E$2:$E$76,Src_Locations!$B$2:$B$76,A9) | L9: =ABS(J9-K9)/J9 | M9: =COUNTIF(Src_Locations!$B$2:$B$76,A9) | N9: =COUNTIFS(Src_Locations!$B$2:$B$76,A9,Src_Locations!$G$2:$G$76,">0") | O9: N | P9: =SUMIFS(Src_Locations!$P$2:$P$76,Src_Locations!$B$2:$B$76,A9) | Q9: =COUNTIFS(Src_Locations!$B$2:$B$76,A9,Src_Locations!$L$2:$L$76,"pending_fence_po") | R9: =COUNTIFS(Src_Locations!$B$2:$B$76,A9,Src_Locations!$I$2:$I$76,"Y") | S9: =SUMIFS(Src_Locations!$R$2:$R$76,Src_Locations!$B$2:$B$76,A9) | T9: 0.943 | U9: 0.268 | V9: =SUMIFS(Src_LossRun!$J$2:$J$43,Src_LossRun!$C$2:$C$43,A9)/D9 | W9: =_xlfn.MAXIFS(Src_Locations!$Q$2:$Q$76,Src_Locations!$B$2:$B$76,A9) | X9: =IF(B9="Campus Edge Housing Co.",1,0) | Y9: =IF(V9>=Executive_Summary!$C$8,1,0) | Z9: =IF(S9>0,1,0) | AA9: =(V9>=Executive_Summary!$C$9)+(W9>=Executive_Summary!$C$10)+(I9>Executive_Summary!$C$11)+(L9>Executive_Summary!$C$12)+(P9>0)+(Q9>0)+(N9>0)+(X9=1) | AB9: =IF(Y9=1,"Decline",IF(Z9=1,"Ask Broker",IF(AA9>0,"Refer","Quote"))) | AC9: Sec 3-6 | AD9: LR 16.4%, no Section 3 trigger. Units and TIV match within tolerance, inspections within the 30-day window, no subsidized units or pool flags. Quote per granite_ridge_routing_notes.txt.
A10: GR-2024 | B10: Irving Park Rentals Inc | C10: IL | D10: 67304.53 | E10: Quoted | F10: Y | G10: 116 | H10: =SUMIFS(Src_Locations!$F$2:$F$76,Src_Locations!$B$2:$B$76,A10) | I10: =ABS(G10-H10)/G10 | J10: 13032989 | K10: =SUMIFS(Src_Locations!$E$2:$E$76,Src_Locations!$B$2:$B$76,A10) | L10: =ABS(J10-K10)/J10 | M10: =COUNTIF(Src_Locations!$B$2:$B$76,A10) | N10: =COUNTIFS(Src_Locations!$B$2:$B$76,A10,Src_Locations!$G$2:$G$76,">0") | O10: N | P10: =SUMIFS(Src_Locations!$P$2:$P$76,Src_Locations!$B$2:$B$76,A10) | Q10: =COUNTIFS(Src_Locations!$B$2:$B$76,A10,Src_Locations!$L$2:$L$76,"pending_fence_po") | R10: =COUNTIFS(Src_Locations!$B$2:$B$76,A10,Src_Locations!$I$2:$I$76,"Y") | S10: =SUMIFS(Src_Locations!$R$2:$R$76,Src_Locations!$B$2:$B$76,A10) | T10: 0.954 | U10: 0.174 | V10: =SUMIFS(Src_LossRun!$J$2:$J$43,Src_LossRun!$C$2:$C$43,A10)/D10 | W10: =_xlfn.MAXIFS(Src_Locations!$Q$2:$Q$76,Src_Locations!$B$2:$B$76,A10) | X10: =IF(B10="Campus Edge Housing Co.",1,0) | Y10: =IF(V10>=Executive_Summary!$C$8,1,0) | Z10: =IF(S10>0,1,0) | AA10: =(V10>=Executive_Summary!$C$9)+(W10>=Executive_Summary!$C$10)+(I10>Executive_Summary!$C$11)+(L10>Executive_Summary!$C$12)+(P10>0)+(Q10>0)+(N10>0)+(X10=1) | AB10: =IF(Y10=1,"Decline",IF(Z10=1,"Ask Broker",IF(AA10>0,"Refer","Quote"))) | AC10: Sec 3-6 | AD10: Recomputed LR 27.7%, well under Section 3 thresholds. Location schedule reconciles within tolerance. Inspections current. Quote per granite_ridge_routing_notes.txt.
A11: GR-2027 | B11: Jefferson Grove MF LLC | C11: OH | D11: 53257.33 | E11: Quoted | F11: Y | G11: 132 | H11: =SUMIFS(Src_Locations!$F$2:$F$76,Src_Locations!$B$2:$B$76,A11) | I11: =ABS(G11-H11)/G11 | J11: 8723089 | K11: =SUMIFS(Src_Locations!$E$2:$E$76,Src_Locations!$B$2:$B$76,A11) | L11: =ABS(J11-K11)/J11 | M11: =COUNTIF(Src_Locations!$B$2:$B$76,A11) | N11: =COUNTIFS(Src_Locations!$B$2:$B$76,A11,Src_Locations!$G$2:$G$76,">0") | O11: N | P11: =SUMIFS(Src_Locations!$P$2:$P$76,Src_Locations!$B$2:$B$76,A11) | Q11: =COUNTIFS(Src_Locations!$B$2:$B$76,A11,Src_Locations!$L$2:$L$76,"pending_fence_po") | R11: =COUNTIFS(Src_Locations!$B$2:$B$76,A11,Src_Locations!$I$2:$I$76,"Y") | S11: =SUMIFS(Src_Locations!$R$2:$R$76,Src_Locations!$B$2:$B$76,A11) | T11: 0.967 | U11: 0.216 | V11: =SUMIFS(Src_LossRun!$J$2:$J$43,Src_LossRun!$C$2:$C$43,A11)/D11 | W11: =_xlfn.MAXIFS(Src_Locations!$Q$2:$Q$76,Src_Locations!$B$2:$B$76,A11) | X11: =IF(B11="Campus Edge Housing Co.",1,0) | Y11: =IF(V11>=Executive_Summary!$C$8,1,0) | Z11: =IF(S11>0,1,0) | AA11: =(V11>=Executive_Summary!$C$9)+(W11>=Executive_Summary!$C$10)+(I11>Executive_Summary!$C$11)+(L11>Executive_Summary!$C$12)+(P11>0)+(Q11>0)+(N11>0)+(X11=1) | AB11: =IF(Y11=1,"Decline",IF(Z11=1,"Ask Broker",IF(AA11>0,"Refer","Quote"))) | AC11: Sec 3-6 | AD11: Section 3 LR 11.6% is below 45%. Schedule reconciliation, inspections, subsidized-housing check, and pool check all clear. Quote per granite_ridge_routing_notes.txt.
A12: GR-2030 | B12: Kenwood Station Apts | C12: IN | D12: 62730.46 | E12: Quoted | F12: Y | G12: 68 | H12: =SUMIFS(Src_Locations!$F$2:$F$76,Src_Locations!$B$2:$B$76,A12) | I12: =ABS(G12-H12)/G12 | J12: 13985036 | K12: =SUMIFS(Src_Locations!$E$2:$E$76,Src_Locations!$B$2:$B$76,A12) | L12: =ABS(J12-K12)/J12 | M12: =COUNTIF(Src_Locations!$B$2:$B$76,A12) | N12: =COUNTIFS(Src_Locations!$B$2:$B$76,A12,Src_Locations!$G$2:$G$76,">0") | O12: N | P12: =SUMIFS(Src_Locations!$P$2:$P$76,Src_Locations!$B$2:$B$76,A12) | Q12: =COUNTIFS(Src_Locations!$B$2:$B$76,A12,Src_Locations!$L$2:$L$76,"pending_fence_po") | R12: =COUNTIFS(Src_Locations!$B$2:$B$76,A12,Src_Locations!$I$2:$I$76,"Y") | S12: =SUMIFS(Src_Locations!$R$2:$R$76,Src_Locations!$B$2:$B$76,A12) | T12: 0.921 | U12: 0.219 | V12: =SUMIFS(Src_LossRun!$J$2:$J$43,Src_LossRun!$C$2:$C$43,A12)/D12 | W12: =_xlfn.MAXIFS(Src_Locations!$Q$2:$Q$76,Src_Locations!$B$2:$B$76,A12) | X12: =IF(B12="Campus Edge Housing Co.",1,0) | Y12: =IF(V12>=Executive_Summary!$C$8,1,0) | Z12: =IF(S12>0,1,0) | AA12: =(V12>=Executive_Summary!$C$9)+(W12>=Executive_Summary!$C$10)+(I12>Executive_Summary!$C$11)+(L12>Executive_Summary!$C$12)+(P12>0)+(Q12>0)+(N12>0)+(X12=1) | AB12: =IF(Y12=1,"Decline",IF(Z12=1,"Ask Broker",IF(AA12>0,"Refer","Quote"))) | AC12: Sec 3-6 | AD12: Clean on all routing checks. Attritional LR 9.4%; schedule data reconciles; life-safety inspections current; no pool or subsidy flags. Quote per granite_ridge_routing_notes.txt.
A13: GR-2033 | B13: Lincolnwood Place LLC | C13: MN | D13: 52180 | E13: Quoted | F13: Y | G13: 72 | H13: =SUMIFS(Src_Locations!$F$2:$F$76,Src_Locations!$B$2:$B$76,A13) | I13: =ABS(G13-H13)/G13 | J13: 6840000 | K13: =SUMIFS(Src_Locations!$E$2:$E$76,Src_Locations!$B$2:$B$76,A13) | L13: =ABS(J13-K13)/J13 | M13: =COUNTIF(Src_Locations!$B$2:$B$76,A13) | N13: =COUNTIFS(Src_Locations!$B$2:$B$76,A13,Src_Locations!$G$2:$G$76,">0") | O13: N | P13: =SUMIFS(Src_Locations!$P$2:$P$76,Src_Locations!$B$2:$B$76,A13) | Q13: =COUNTIFS(Src_Locations!$B$2:$B$76,A13,Src_Locations!$L$2:$L$76,"pending_fence_po") | R13: =COUNTIFS(Src_Locations!$B$2:$B$76,A13,Src_Locations!$I$2:$I$76,"Y") | S13: =SUMIFS(Src_Locations!$R$2:$R$76,Src_Locations!$B$2:$B$76,A13) | T13: 0.884 | U13: 0.192 | V13: =SUMIFS(Src_LossRun!$J$2:$J$43,Src_LossRun!$C$2:$C$43,A13)/D13 | W13: =_xlfn.MAXIFS(Src_Locations!$Q$2:$Q$76,Src_Locations!$B$2:$B$76,A13) | X13: =IF(B13="Campus Edge Housing Co.",1,0) | Y13: =IF(V13>=Executive_Summary!$C$8,1,0) | Z13: =IF(S13>0,1,0) | AA13: =(V13>=Executive_Summary!$C$9)+(W13>=Executive_Summary!$C$10)+(I13>Executive_Summary!$C$11)+(L13>Executive_Summary!$C$12)+(P13>0)+(Q13>0)+(N13>0)+(X13=1) | AB13: =IF(Y13=1,"Decline",IF(Z13=1,"Ask Broker",IF(AA13>0,"Refer","Quote"))) | AC13: Sec 6 | AD13: Section 6 Ask Broker: HAB-2033-B vacancy_flag=Y with broker_confirmation=no in granite_ridge_location_schedule.csv; do not quote until broker updates (queue GRP-BRK-UPD).
... A37: GR-2200 | B37: Indiana Ave Partners LLC | C37: IN | D37: 82603.3 | E37: Quoted | F37: Y | G37: 153 | H37: =SUMIFS(Src_Locations!$F$2:$F$76,Src_Locations!$B$2:$B$76,A37) | I37: =ABS(G37-H37)/G37 | J37: 11805363 | K37: =SUMIFS(Src_Locations!$E$2:$E$76,Src_Locations!$B$2:$B$76,A37) | L37: =ABS(J37-K37)/J37 | M37: =COUNTIF(Src_Locations!$B$2:$B$76,A37) | N37: =COUNTIFS(Src_Locations!$B$2:$B$76,A37,Src_Locations!$G$2:$G$76,">0") | O37: N | P37: =SUMIFS(Src_Locations!$P$2:$P$76,Src_Locations!$B$2:$B$76,A37) | Q37: =COUNTIFS(Src_Locations!$B$2:$B$76,A37,Src_Locations!$L$2:$L$76,"pending_fence_po") | R37: =COUNTIFS(Src_Locations!$B$2:$B$76,A37,Src_Locations!$I$2:$I$76,"Y") | S37: =SUMIFS(Src_Locations!$R$2:$R$76,Src_Locations!$B$2:$B$76,A37) | T37: 0.943 | U37: 0.263 | V37: =SUMIFS(Src_LossRun!$J$2:$J$43,Src_LossRun!$C$2:$C$43,A37)/D37 | W37: =_xlfn.MAXIFS(Src_Locations!$Q$2:$Q$76,Src_Locations!$B$2:$B$76,A37) | X37: =IF(B37="Campus Edge Housing Co.",1,0) | Y37: =IF(V37>=Executive_Summary!$C$8,1,0) | Z37: =IF(S37>0,1,0) | AA37: =(V37>=Executive_Summary!$C$9)+(W37>=Executive_Summary!$C$10)+(I37>Executive_Summary!$C$11)+(L37>Executive_Summary!$C$12)+(P37>0)+(Q37>0)+(N37>0)+(X37=1) | AB37: =IF(Y37=1,"Decline",IF(Z37=1,"Ask Broker",IF(AA37>0,"Refer","Quote"))) | AC37: Sec 3-6 | AD37: Section 3 LR 16.6% is below 45%. Schedule reconciliation, inspections, subsidized-housing check, and pool check all clear. Quote per granite_ridge_routing_notes.txt.

Sheet Location_Exceptions
A1: account_id | B1: location_id | C1: field | D1: source_value | E1: threshold_or_conflicting_value | F1: exception_type | G1: impact_on_routing | H1: resolution / required action | I1: rule_reference | J1: source_file
A2: GR-2007 | B2: Account level | C2: named_insured | D2: Campus Edge Housing Co. (student housing) | E2: Section 10 appetite note applies even with no vacancy_flag set | F2: Student-housing appetite note | G2: Refer (mandatory pre-bind review; judgment, see Decision_Notes note 4) | H2: GRP-APPETITE review must be submitted before bind. No CUO clearance memo is in the file package, so clearance is NOT assumed. Seasonal-vacancy questions go to GRP-APPETITE. | I2: granite_ridge_routing_notes.txt Section 10 | J2: granite_ridge_renewal_accounts.csv; granite_ridge_routing_notes.txt
A3: GR-2033 | B3: HAB-2033-B | C3: vacancy_flag / broker_confirmation | D3: Y / no | E3: Y with broker_confirmation = no | F3: Vacancy not confirmed by broker | G3: Ask Broker; do not quote until updated | H3: Request vacancy/turnover confirmation via queue GRP-BRK-UPD. Account occupancy 88.4% is consistent with a vacant location; summary occupancy cannot be relied on alone. | I3: granite_ridge_routing_notes.txt Section 6 | J3: granite_ridge_location_schedule.csv
A4: GR-2047 | B4: HAB-2047-B | C4: vacancy_flag / broker_confirmation | D4: Y / yes | E4: Y with broker_confirmation = yes | F4: Vacancy documented by broker (informational) | G4: None: Ask Broker not triggered; Refer vacancy trigger not met (documented; occupancy 94.0% not full) | H4: Quote retained. Judgment call documented on Decision_Notes (note 3). Reopen if desk requires a separate turnover-exception document. | I4: granite_ridge_routing_notes.txt Section 6 | J4: granite_ridge_location_schedule.csv
A5: GR-2053 | B5: HAB-2053-A | C5: subsidized_unit_count | D5: 24 | E5: > 0 triggers referral | F5: Subsidized housing | G5: Refer before Quote | H5: Obtain subsidized-housing endorsement documentation; route via queue GRP-SUB-HAB. Account list subsidized_housing_flag = Y agrees with schedule. | I5: granite_ridge_routing_notes.txt Section 6 | J5: granite_ridge_location_schedule.csv
A6: GR-2065 | B6: Account level | C6: named_insured | D6: Campus Edge Housing Co. (student housing) | E6: Section 10 appetite note applies even with no vacancy_flag set | F6: Student-housing appetite note | G6: Refer (mandatory pre-bind review; judgment, see Decision_Notes note 4) | H6: GRP-APPETITE review must be submitted before bind. No CUO clearance memo is in the file package, so clearance is NOT assumed. Seasonal-vacancy questions go to GRP-APPETITE. | I6: granite_ridge_routing_notes.txt Section 10 | J6: granite_ridge_renewal_accounts.csv; granite_ridge_routing_notes.txt
A7: GR-2068 | B7: HAB-2068-B | C7: subsidized_unit_count | D7: 18 | E7: > 0 triggers referral | F7: Subsidized housing | G7: Refer before Quote | H7: Obtain subsidized-housing endorsement documentation; route via queue GRP-SUB-HAB. Account list subsidized_housing_flag = Y agrees with schedule. | I7: granite_ridge_routing_notes.txt Section 6 | J7: granite_ridge_location_schedule.csv
A8: GR-2071 | B8: HAB-2071-A | C8: cat_code | D8: CAT-2408; $284,600.00 paid (Wind, 2024-08-19) | E8: Section 9 default: exclude cat rows from Section 3 thresholds | F8: Catastrophe-coded loss excluded | G8: None (excluded); Quote retained | H8: Tracked separately. CUO memo GRP-CAT-2025-03 is not in the file package, so default exclusion applied. | I8: granite_ridge_routing_notes.txt Section 9 | J8: granite_ridge_loss_run_36mo.csv
A9: GR-2074 | B9: HAB-2074-A | C9: pool_liability_flag | D9: pending_fence_po | E9: Must be cleared with completion evidence | F9: Pool fence remediation pending | G9: Refer | H9: Hold until fence completion evidence is uploaded. | I9: granite_ridge_routing_notes.txt Section 5 | J9: granite_ridge_location_schedule.csv
A10: GR-2089 | B10: HAB-2089-A | C10: sprinkler_inspection_date | D10: 2025-04-02 | E10: Cutoff: on or after 2025-09-01 (30 days before 2025-10-01); actual 182 days before | F10: Life-safety inspection lapse | G10: Refer | H10: No renewed certificate in file package; obtain renewed sprinkler and fire alarm certificates before bind. | I10: granite_ridge_routing_notes.txt Section 5 | J10: granite_ridge_location_schedule.csv
A11: GR-2089 | B11: HAB-2089-A | C11: fire_alarm_inspection_date | D11: 2025-04-02 | E11: Cutoff: on or after 2025-09-01 (30 days before 2025-10-01); actual 182 days before | F11: Life-safety inspection lapse | G11: Refer | H11: No renewed certificate in file package; obtain renewed sprinkler and fire alarm certificates before bind. | I11: granite_ridge_routing_notes.txt Section 5 | J11: granite_ridge_location_schedule.csv
A12: GR-2092 | B12: HAB-2092-A | C12: subsidized_unit_count | D12: 22 | E12: > 0 triggers referral | F12: Subsidized housing | G12: Refer before Quote | H12: Obtain subsidized-housing endorsement documentation; route via queue GRP-SUB-HAB. Account list subsidized_housing_flag = Y agrees with schedule. | I12: granite_ridge_routing_notes.txt Section 6 | J12: granite_ridge_location_schedule.csv
A13: GR-2113 | B13: Account level (all 3 locations) | C13: unit_count | D13: List 142 vs schedule sum 150 (variance 8 units, 5.63%) | E13: Refer if variance > 5% of list unit_count | F13: Unit count does not tie | G13: Refer | H13: Schedule governs unit counts (Section 1 item 3); obtain corrected account unit count / confirm added units. | I13: granite_ridge_routing_notes.txt Section 4 | J13: granite_ridge_renewal_accounts.csv; granite_ridge_location_schedule.csv
A14: GR-2113 | B14: Account level (all 3 locations) | C14: account_tiv vs building_tiv | D14: List $11,840,000 vs schedule sum $12,810,880 (variance $970,880, 8.20%) | E14: Refer if variance > 3% of list TIV | F14: TIV does not tie | G14: Refer | H14: Schedule governs TIV; confirm valuation and re-rate on schedule TIV. | I14: granite_ridge_routing_notes.txt Section 4 | J14: granite_ridge_renewal_accounts.csv; granite_ridge_location_schedule.csv
A15: GR-2162 | B15: HAB-2162-C | C15: total incurred (paid + reserved, 36 mo) | D15: $260,120.00 (paid $187,640 + reserved $72,480) | E15: Refer if any single location >= $250,000 | F15: Large single-location loss (Fire, 2024-09-14) | G15: Refer | H15: Obtain claim status and large-loss review; account list LR of 31.8% did not show this. | I15: granite_ridge_routing_notes.txt Section 3 | J15: granite_ridge_loss_run_36mo.csv
A17: Location-level exception detail for every one of the 75 schedule rows (dates, days before effective date, lapse and vacancy flags) is on Src_Locations columns N-R.

Sheet Loss_Reconciliation
A1: account_id | B1: named_insured | C1: expiring_premium | D1: list_loss_ratio (accounts.csv) | E1: loss_run_rows | F1: gross_incurred_all_rows (paid+reserved) | G1: cat_coded_incurred (excluded, Sec 9) | H1: attritional_incurred (paid+reserved, cat blank) | I1: recomputed_attritional_LR (Sec 3) | J1: delta_points (recomputed - list) | K1: differs_by_more_than_5_pts | L1: max_single_location_incurred | M1: Section 3 result | N1: final_LR_used_for_routing | O1: disposition | P1: routing_impact / comment
A2: GR-2001 | B2: Ashland Court Apts LP | C2: =Account_Routing!D2 | D2: =Account_Routing!U2 | E2: =COUNTIF(Src_LossRun!$C$2:$C$43,A2) | F2: =SUMIFS(Src_LossRun!$I$2:$I$43,Src_LossRun!$C$2:$C$43,A2) | G2: =F2-H2 | H2: =SUMIFS(Src_LossRun!$J$2:$J$43,Src_LossRun!$C$2:$C$43,A2) | I2: =H2/C2 | J2: =(I2-D2)*100 | K2: =IF(ABS(J2)>5,"Yes","No") | L2: =Account_Routing!W2 | M2: =IF(I2>=Executive_Summary!$C$8,"Decline (LR >= 70%)",IF(I2>=Executive_Summary!$C$9,"Refer (LR 45%-70%)",IF(L2>=Executive_Summary!$C$10,"Refer (single location >= $250k)","Clear"))) | N2: =I2 | O2: =Account_Routing!AB2 | P2: =IF(K2="Yes","List ratio is stale vs loss run; recomputed ratio used per Section 1 item 2. No Section 3 trigger.","Within 5 points of list; recomputed ratio used. No Section 3 trigger.")
A3: GR-2004 | B3: Berwyn Arms LLC | C3: =Account_Routing!D3 | D3: =Account_Routing!U3 | E3: =COUNTIF(Src_LossRun!$C$2:$C$43,A3) | F3: =SUMIFS(Src_LossRun!$I$2:$I$43,Src_LossRun!$C$2:$C$43,A3) | G3: =F3-H3 | H3: =SUMIFS(Src_LossRun!$J$2:$J$43,Src_LossRun!$C$2:$C$43,A3) | I3: =H3/C3 | J3: =(I3-D3)*100 | K3: =IF(ABS(J3)>5,"Yes","No") | L3: =Account_Routing!W3 | M3: =IF(I3>=Executive_Summary!$C$8,"Decline (LR >= 70%)",IF(I3>=Executive_Summary!$C$9,"Refer (LR 45%-70%)",IF(L3>=Executive_Summary!$C$10,"Refer (single location >= $250k)","Clear"))) | N3: =I3 | O3: =Account_Routing!AB3 | P3: =IF(K3="Yes","List ratio is stale vs loss run; recomputed ratio used per Section 1 item 2. No Section 3 trigger.","Within 5 points of list; recomputed ratio used. No Section 3 trigger.")
A4: GR-2007 | B4: Campus Edge Housing Co. | C4: =Account_Routing!D4 | D4: =Account_Routing!U4 | E4: =COUNTIF(Src_LossRun!$C$2:$C$43,A4) | F4: =SUMIFS(Src_LossRun!$I$2:$I$43,Src_LossRun!$C$2:$C$43,A4) | G4: =F4-H4 | H4: =SUMIFS(Src_LossRun!$J$2:$J$43,Src_LossRun!$C$2:$C$43,A4) | I4: =H4/C4 | J4: =(I4-D4)*100 | K4: =IF(ABS(J4)>5,"Yes","No") | L4: =Account_Routing!W4 | M4: =IF(I4>=Executive_Summary!$C$8,"Decline (LR >= 70%)",IF(I4>=Executive_Summary!$C$9,"Refer (LR 45%-70%)",IF(L4>=Executive_Summary!$C$10,"Refer (single location >= $250k)","Clear"))) | N4: =I4 | O4: =Account_Routing!AB4 | P4: =IF(K4="Yes","List ratio is stale vs loss run; recomputed ratio used per Section 1 item 2. No Section 3 trigger.","Within 5 points of list; recomputed ratio used. No Section 3 trigger.")
A5: GR-2010 | B5: Damen Square Residences | C5: =Account_Routing!D5 | D5: =Account_Routing!U5 | E5: =COUNTIF(Src_LossRun!$C$2:$C$43,A5) | F5: =SUMIFS(Src_LossRun!$I$2:$I$43,Src_LossRun!$C$2:$C$43,A5) | G5: =F5-H5 | H5: =SUMIFS(Src_LossRun!$J$2:$J$43,Src_LossRun!$C$2:$C$43,A5) | I5: =H5/C5 | J5: =(I5-D5)*100 | K5: =IF(ABS(J5)>5,"Yes","No") | L5: =Account_Routing!W5 | M5: =IF(I5>=Executive_Summary!$C$8,"Decline (LR >= 70%)",IF(I5>=Executive_Summary!$C$9,"Refer (LR 45%-70%)",IF(L5>=Executive_Summary!$C$10,"Refer (single location >= $250k)","Clear"))) | N5: =I5 | O5: =Account_Routing!AB5 | P5: =IF(K5="Yes","List ratio is stale vs loss run; recomputed ratio used per Section 1 item 2. No Section 3 trigger.","Within 5 points of list; recomputed ratio used. No Section 3 trigger.")
A6: GR-2013 | B6: Eastgate Manor LLC | C6: =Account_Routing!D6 | D6: =Account_Routing!U6 | E6: =COUNTIF(Src_LossRun!$C$2:$C$43,A6) | F6: =SUMIFS(Src_LossRun!$I$2:$I$43,Src_LossRun!$C$2:$C$43,A6) | G6: =F6-H6 | H6: =SUMIFS(Src_LossRun!$J$2:$J$43,Src_LossRun!$C$2:$C$43,A6) | I6: =H6/C6 | J6: =(I6-D6)*100 | K6: =IF(ABS(J6)>5,"Yes","No") | L6: =Account_Routing!W6 | M6: =IF(I6>=Executive_Summary!$C$8,"Decline (LR >= 70%)",IF(I6>=Executive_Summary!$C$9,"Refer (LR 45%-70%)",IF(L6>=Executive_Summary!$C$10,"Refer (single location >= $250k)","Clear"))) | N6: =I6 | O6: =Account_Routing!AB6 | P6: =IF(K6="Yes","List ratio is stale vs loss run; recomputed ratio used per Section 1 item 2. No Section 3 trigger.","Within 5 points of list; recomputed ratio used. No Section 3 trigger.")
A7: GR-2016 | B7: Fairmount Village Apts | C7: =Account_Routing!D7 | D7: =Account_Routing!U7 | E7: =COUNTIF(Src_LossRun!$C$2:$C$43,A7) | F7: =SUMIFS(Src_LossRun!$I$2:$I$43,Src_LossRun!$C$2:$C$43,A7) | G7: =F7-H7 | H7: =SUMIFS(Src_LossRun!$J$2:$J$43,Src_LossRun!$C$2:$C$43,A7) | I7: =H7/C7 | J7: =(I7-D7)*100 | K7: =IF(ABS(J7)>5,"Yes","No") | L7: =Account_Routing!W7 | M7: =IF(I7>=Executive_Summary!$C$8,"Decline (LR >= 70%)",IF(I7>=Executive_Summary!$C$9,"Refer (LR 45%-70%)",IF(L7>=Executive_Summary!$C$10,"Refer (single location >= $250k)","Clear"))) | N7: =I7 | O7: =Account_Routing!AB7 | P7: =IF(K7="Yes","List ratio is stale vs loss run; recomputed ratio used per Section 1 item 2. No Section 3 trigger.","Within 5 points of list; recomputed ratio used. No Section 3 trigger.")
A8: GR-2018 | B8: Glenwood Terrace LLC | C8: =Account_Routing!D8 | D8: =Account_Routing!U8 | E8: =COUNTIF(Src_LossRun!$C$2:$C$43,A8) | F8: =SUMIFS(Src_LossRun!$I$2:$I$43,Src_LossRun!$C$2:$C$43,A8) | G8: =F8-H8 | H8: =SUMIFS(Src_LossRun!$J$2:$J$43,Src_LossRun!$C$2:$C$43,A8) | I8: =H8/C8 | J8: =(I8-D8)*100 | K8: =IF(ABS(J8)>5,"Yes","No") | L8: =Account_Routing!W8 | M8: =IF(I8>=Executive_Summary!$C$8,"Decline (LR >= 70%)",IF(I8>=Executive_Summary!$C$9,"Refer (LR 45%-70%)",IF(L8>=Executive_Summary!$C$10,"Refer (single location >= $250k)","Clear"))) | N8: =I8 | O8: =Account_Routing!AB8 | P8: =IF(K8="Yes","List ratio is stale vs loss run; recomputed ratio used per Section 1 item 2. No Section 3 trigger.","Within 5 points of list; recomputed ratio used. No Section 3 trigger.")
A9: GR-2021 | B9: Halsted Walkup Partners | C9: =Account_Routing!D9 | D9: =Account_Routing!U9 | E9: =COUNTIF(Src_LossRun!$C$2:$C$43,A9) | F9: =SUMIFS(Src_LossRun!$I$2:$I$43,Src_LossRun!$C$2:$C$43,A9) | G9: =F9-H9 | H9: =SUMIFS(Src_LossRun!$J$2:$J$43,Src_LossRun!$C$2:$C$43,A9) | I9: =H9/C9 | J9: =(I9-D9)*100 | K9: =IF(ABS(J9)>5,"Yes","No") | L9: =Account_Routing!W9 | M9: =IF(I9>=Executive_Summary!$C$8,"Decline (LR >= 70%)",IF(I9>=Executive_Summary!$C$9,"Refer (LR 45%-70%)",IF(L9>=Executive_Summary!$C$10,"Refer (single location >= $250k)","Clear"))) | N9: =I9 | O9: =Account_Routing!AB9 | P9: =IF(K9="Yes","List ratio is stale vs loss run; recomputed ratio used per Section 1 item 2. No Section 3 trigger.","Within 5 points of list; recomputed ratio used. No Section 3 trigger.")
A10: GR-2024 | B10: Irving Park Rentals Inc | C10: =Account_Routing!D10 | D10: =Account_Routing!U10 | E10: =COUNTIF(Src_LossRun!$C$2:$C$43,A10) | F10: =SUMIFS(Src_LossRun!$I$2:$I$43,Src_LossRun!$C$2:$C$43,A10) | G10: =F10-H10 | H10: =SUMIFS(Src_LossRun!$J$2:$J$43,Src_LossRun!$C$2:$C$43,A10) | I10: =H10/C10 | J10: =(I10-D10)*100 | K10: =IF(ABS(J10)>5,"Yes","No") | L10: =Account_Routing!W10 | M10: =IF(I10>=Executive_Summary!$C$8,"Decline (LR >= 70%)",IF(I10>=Executive_Summary!$C$9,"Refer (LR 45%-70%)",IF(L10>=Executive_Summary!$C$10,"Refer (single location >= $250k)","Clear"))) | N10: =I10 | O10: =Account_Routing!AB10 | P10: =IF(K10="Yes","List ratio is stale vs loss run; recomputed ratio used per Section 1 item 2. No Section 3 trigger.","Within 5 points of list; recomputed ratio used. No Section 3 trigger.")
A11: GR-2027 | B11: Jefferson Grove MF LLC | C11: =Account_Routing!D11 | D11: =Account_Routing!U11 | E11: =COUNTIF(Src_LossRun!$C$2:$C$43,A11) | F11: =SUMIFS(Src_LossRun!$I$2:$I$43,Src_LossRun!$C$2:$C$43,A11) | G11: =F11-H11 | H11: =SUMIFS(Src_LossRun!$J$2:$J$43,Src_LossRun!$C$2:$C$43,A11) | I11: =H11/C11 | J11: =(I11-D11)*100 | K11: =IF(ABS(J11)>5,"Yes","No") | L11: =Account_Routing!W11 | M11: =IF(I11>=Executive_Summary!$C$8,"Decline (LR >= 70%)",IF(I11>=Executive_Summary!$C$9,"Refer (LR 45%-70%)",IF(L11>=Executive_Summary!$C$10,"Refer (single location >= $250k)","Clear"))) | N11: =I11 | O11: =Account_Routing!AB11 | P11: =IF(K11="Yes","List ratio is stale vs loss run; recomputed ratio used per Section 1 item 2. No Section 3 trigger.","Within 5 points of list; recomputed ratio used. No Section 3 trigger.")
A12: GR-2030 | B12: Kenwood Station Apts | C12: =Account_Routing!D12 | D12: =Account_Routing!U12 | E12: =COUNTIF(Src_LossRun!$C$2:$C$43,A12) | F12: =SUMIFS(Src_LossRun!$I$2:$I$43,Src_LossRun!$C$2:$C$43,A12) | G12: =F12-H12 | H12: =SUMIFS(Src_LossRun!$J$2:$J$43,Src_LossRun!$C$2:$C$43,A12) | I12: =H12/C12 | J12: =(I12-D12)*100 | K12: =IF(ABS(J12)>5,"Yes","No") | L12: =Account_Routing!W12 | M12: =IF(I12>=Executive_Summary!$C$8,"Decline (LR >= 70%)",IF(I12>=Executive_Summary!$C$9,"Refer (LR 45%-70%)",IF(L12>=Executive_Summary!$C$10,"Refer (single location >= $250k)","Clear"))) | N12: =I12 | O12: =Account_Routing!AB12 | P12: =IF(K12="Yes","List ratio is stale vs loss run; recomputed ratio used per Section 1 item 2. No Section 3 trigger.","Within 5 points of list; recomputed ratio used. No Section 3 trigger.")
A13: GR-2033 | B13: Lincolnwood Place LLC | C13: =Account_Routing!D13 | D13: =Account_Routing!U13 | E13: =COUNTIF(Src_LossRun!$C$2:$C$43,A13) | F13: =SUMIFS(Src_LossRun!$I$2:$I$43,Src_LossRun!$C$2:$C$43,A13) | G13: =F13-H13 | H13: =SUMIFS(Src_LossRun!$J$2:$J$43,Src_LossRun!$C$2:$C$43,A13) | I13: =H13/C13 | J13: =(I13-D13)*100 | K13: =IF(ABS(J13)>5,"Yes","No") | L13: =Account_Routing!W13 | M13: =IF(I13>=Executive_Summary!$C$8,"Decline (LR >= 70%)",IF(I13>=Executive_Summary!$C$9,"Refer (LR 45%-70%)",IF(L13>=Executive_Summary!$C$10,"Refer (single location >= $250k)","Clear"))) | N13: =I13 | O13: =Account_Routing!AB13 | P13: =IF(K13="Yes","List ratio is stale vs loss run; recomputed ratio used per Section 1 item 2. No Section 3 trigger.","Within 5 points of list; recomputed ratio used. No Section 3 trigger.")
... A25: GR-2068 | B25: Westchester Court LLC | C25: =Account_Routing!D25 | D25: =Account_Routing!U25 | E25: =COUNTIF(Src_LossRun!$C$2:$C$43,A25) | F25: =SUMIFS(Src_LossRun!$I$2:$I$43,Src_LossRun!$C$2:$C$43,A25) | G25: =F25-H25 | H25: =SUMIFS(Src_LossRun!$J$2:$J$43,Src_LossRun!$C$2:$C$43,A25) | I25: =H25/C25 | J25: =(I25-D25)*100 | K25: =IF(ABS(J25)>5,"Yes","No") | L25: =Account_Routing!W25 | M25: =IF(I25>=Executive_Summary!$C$8,"Decline (LR >= 70%)",IF(I25>=Executive_Summary!$C$9,"Refer (LR 45%-70%)",IF(L25>=Executive_Summary!$C$10,"Refer (single location >= $250k)","Clear"))) | N25: =I25 | O25: =Account_Routing!AB25 | P25: =IF(K25="Yes","List ratio is stale vs loss run; recomputed ratio used per Section 1 item 2. No Section 3 trigger.","Within 5 points of list; recomputed ratio used. No Section 3 trigger.")
A26: GR-2071 | B26: Buckeye Garden Apts LLC | C26: =Account_Routing!D26 | D26: =Account_Routing!U26 | E26: =COUNTIF(Src_LossRun!$C$2:$C$43,A26) | F26: =SUMIFS(Src_LossRun!$I$2:$I$43,Src_LossRun!$C$2:$C$43,A26) | G26: =F26-H26 | H26: =SUMIFS(Src_LossRun!$J$2:$J$43,Src_LossRun!$C$2:$C$43,A26) | I26: =H26/C26 | J26: =(I26-D26)*100 | K26: =IF(ABS(J26)>5,"Yes","No") | L26: =Account_Routing!W26 | M26: =IF(I26>=Executive_Summary!$C$8,"Decline (LR >= 70%)",IF(I26>=Executive_Summary!$C$9,"Refer (LR 45%-70%)",IF(L26>=Executive_Summary!$C$10,"Refer (single location >= $250k)","Clear"))) | N26: =I26 | O26: =Account_Routing!AB26 | P26: Cat-coded CAT-2408 loss ($284,600) excluded per Section 9; attritional LR unchanged from routing view. Would be Refer on single-location test if CUO memo GRP-CAT-2025-03 applied (memo not in package).
A27: GR-2074 | B27: Yorktown Flats LLC | C27: =Account_Routing!D27 | D27: =Account_Routing!U27 | E27: =COUNTIF(Src_LossRun!$C$2:$C$43,A27) | F27: =SUMIFS(Src_LossRun!$I$2:$I$43,Src_LossRun!$C$2:$C$43,A27) | G27: =F27-H27 | H27: =SUMIFS(Src_LossRun!$J$2:$J$43,Src_LossRun!$C$2:$C$43,A27) | I27: =H27/C27 | J27: =(I27-D27)*100 | K27: =IF(ABS(J27)>5,"Yes","No") | L27: =Account_Routing!W27 | M27: =IF(I27>=Executive_Summary!$C$8,"Decline (LR >= 70%)",IF(I27>=Executive_Summary!$C$9,"Refer (LR 45%-70%)",IF(L27>=Executive_Summary!$C$10,"Refer (single location >= $250k)","Clear"))) | N27: =I27 | O27: =Account_Routing!AB27 | P27: =IF(K27="Yes","List ratio is stale vs loss run; recomputed ratio used per Section 1 item 2. No Section 3 trigger.","Within 5 points of list; recomputed ratio used. No Section 3 trigger.")
A28: GR-2077 | B28: Zion Road Residences | C28: =Account_Routing!D28 | D28: =Account_Routing!U28 | E28: =COUNTIF(Src_LossRun!$C$2:$C$43,A28) | F28: =SUMIFS(Src_LossRun!$I$2:$I$43,Src_LossRun!$C$2:$C$43,A28) | G28: =F28-H28 | H28: =SUMIFS(Src_LossRun!$J$2:$J$43,Src_LossRun!$C$2:$C$43,A28) | I28: =H28/C28 | J28: =(I28-D28)*100 | K28: =IF(ABS(J28)>5,"Yes","No") | L28: =Account_Routing!W28 | M28: =IF(I28>=Executive_Summary!$C$8,"Decline (LR >= 70%)",IF(I28>=Executive_Summary!$C$9,"Refer (LR 45%-70%)",IF(L28>=Executive_Summary!$C$10,"Refer (single location >= $250k)","Clear"))) | N28: =I28 | O28: =Account_Routing!AB28 | P28: =IF(K28="Yes","List ratio is stale vs loss run; recomputed ratio used per Section 1 item 2. No Section 3 trigger.","Within 5 points of list; recomputed ratio used. No Section 3 trigger.")
A29: GR-2080 | B29: Archer Avenue Apts LLC | C29: =Account_Routing!D29 | D29: =Account_Routing!U29 | E29: =COUNTIF(Src_LossRun!$C$2:$C$43,A29) | F29: =SUMIFS(Src_LossRun!$I$2:$I$43,Src_LossRun!$C$2:$C$43,A29) | G29: =F29-H29 | H29: =SUMIFS(Src_LossRun!$J$2:$J$43,Src_LossRun!$C$2:$C$43,A29) | I29: =H29/C29 | J29: =(I29-D29)*100 | K29: =IF(ABS(J29)>5,"Yes","No") | L29: =Account_Routing!W29 | M29: =IF(I29>=Executive_Summary!$C$8,"Decline (LR >= 70%)",IF(I29>=Executive_Summary!$C$9,"Refer (LR 45%-70%)",IF(L29>=Executive_Summary!$C$10,"Refer (single location >= $250k)","Clear"))) | N29: =I29 | O29: =Account_Routing!AB29 | P29: =IF(K29="Yes","List ratio is stale vs loss run; recomputed ratio used per Section 1 item 2. No Section 3 trigger.","Within 5 points of list; recomputed ratio used. No Section 3 trigger.")
A30: GR-2083 | B30: Belmont Court Partners | C30: =Account_Routing!D30 | D30: =Account_Routing!U30 | E30: =COUNTIF(Src_LossRun!$C$2:$C$43,A30) | F30: =SUMIFS(Src_LossRun!$I$2:$I$43,Src_LossRun!$C$2:$C$43,A30) | G30: =F30-H30 | H30: =SUMIFS(Src_LossRun!$J$2:$J$43,Src_LossRun!$C$2:$C$43,A30) | I30: =H30/C30 | J30: =(I30-D30)*100 | K30: =IF(ABS(J30)>5,"Yes","No") | L30: =Account_Routing!W30 | M30: =IF(I30>=Executive_Summary!$C$8,"Decline (LR >= 70%)",IF(I30>=Executive_Summary!$C$9,"Refer (LR 45%-70%)",IF(L30>=Executive_Summary!$C$10,"Refer (single location >= $250k)","Clear"))) | N30: =I30 | O30: =Account_Routing!AB30 | P30: =IF(K30="Yes","List ratio is stale vs loss run; recomputed ratio used per Section 1 item 2. No Section 3 trigger.","Within 5 points of list; recomputed ratio used. No Section 3 trigger.")
A31: GR-2086 | B31: Cermak Place LLC | C31: =Account_Routing!D31 | D31: =Account_Routing!U31 | E31: =COUNTIF(Src_LossRun!$C$2:$C$43,A31) | F31: =SUMIFS(Src_LossRun!$I$2:$I$43,Src_LossRun!$C$2:$C$43,A31) | G31: =F31-H31 | H31: =SUMIFS(Src_LossRun!$J$2:$J$43,Src_LossRun!$C$2:$C$43,A31) | I31: =H31/C31 | J31: =(I31-D31)*100 | K31: =IF(ABS(J31)>5,"Yes","No") | L31: =Account_Routing!W31 | M31: =IF(I31>=Executive_Summary!$C$8,"Decline (LR >= 70%)",IF(I31>=Executive_Summary!$C$9,"Refer (LR 45%-70%)",IF(L31>=Executive_Summary!$C$10,"Refer (single location >= $250k)","Clear"))) | N31: =I31 | O31: =Account_Routing!AB31 | P31: =IF(K31="Yes","List ratio is stale vs loss run; recomputed ratio used per Section 1 item 2. No Section 3 trigger.","Within 5 points of list; recomputed ratio used. No Section 3 trigger.")
A32: GR-2089 | B32: Devonshire Arms LLC | C32: =Account_Routing!D32 | D32: =Account_Routing!U32 | E32: =COUNTIF(Src_LossRun!$C$2:$C$43,A32) | F32: =SUMIFS(Src_LossRun!$I$2:$I$43,Src_LossRun!$C$2:$C$43,A32) | G32: =F32-H32 | H32: =SUMIFS(Src_LossRun!$J$2:$J$43,Src_LossRun!$C$2:$C$43,A32) | I32: =H32/C32 | J32: =(I32-D32)*100 | K32: =IF(ABS(J32)>5,"Yes","No") | L32: =Account_Routing!W32 | M32: =IF(I32>=Executive_Summary!$C$8,"Decline (LR >= 70%)",IF(I32>=Executive_Summary!$C$9,"Refer (LR 45%-70%)",IF(L32>=Executive_Summary!$C$10,"Refer (single location >= $250k)","Clear"))) | N32: =I32 | O32: =Account_Routing!AB32 | P32: =IF(K32="Yes","List ratio is stale vs loss run; recomputed ratio used per Section 1 item 2. No Section 3 trigger.","Within 5 points of list; recomputed ratio used. No Section 3 trigger.")
A33: GR-2092 | B33: Elston Crossing Apts | C33: =Account_Routing!D33 | D33: =Account_Routing!U33 | E33: =COUNTIF(Src_LossRun!$C$2:$C$43,A33) | F33: =SUMIFS(Src_LossRun!$I$2:$I$43,Src_LossRun!$C$2:$C$43,A33) | G33: =F33-H33 | H33: =SUMIFS(Src_LossRun!$J$2:$J$43,Src_LossRun!$C$2:$C$43,A33) | I33: =H33/C33 | J33: =(I33-D33)*100 | K33: =IF(ABS(J33)>5,"Yes","No") | L33: =Account_Routing!W33 | M33: =IF(I33>=Executive_Summary!$C$8,"Decline (LR >= 70%)",IF(I33>=Executive_Summary!$C$9,"Refer (LR 45%-70%)",IF(L33>=Executive_Summary!$C$10,"Refer (single location >= $250k)","Clear"))) | N33: =I33 | O33: =Account_Routing!AB33 | P33: =IF(K33="Yes","List ratio is stale vs loss run; recomputed ratio used per Section 1 item 2. No Section 3 trigger.","Within 5 points of list; recomputed ratio used. No Section 3 trigger.")
A34: GR-2113 | B34: Fulton Market Residences | C34: =Account_Routing!D34 | D34: =Account_Routing!U34 | E34: =COUNTIF(Src_LossRun!$C$2:$C$43,A34) | F34: =SUMIFS(Src_LossRun!$I$2:$I$43,Src_LossRun!$C$2:$C$43,A34) | G34: =F34-H34 | H34: =SUMIFS(Src_LossRun!$J$2:$J$43,Src_LossRun!$C$2:$C$43,A34) | I34: =H34/C34 | J34: =(I34-D34)*100 | K34: =IF(ABS(J34)>5,"Yes","No") | L34: =Account_Routing!W34 | M34: =IF(I34>=Executive_Summary!$C$8,"Decline (LR >= 70%)",IF(I34>=Executive_Summary!$C$9,"Refer (LR 45%-70%)",IF(L34>=Executive_Summary!$C$10,"Refer (single location >= $250k)","Clear"))) | N34: =I34 | O34: =Account_Routing!AB34 | P34: Loss ratio clear (Section 3). Section 4: unit count variance = |142 - 150| / 142 = 5.63% (> 5%); TIV variance = |$11,840,000 - $12,810,880| / $11,840,000 = 8.20% (> 3%). Account routed Refer on Section 4. See also Location_Exceptions.
A35: GR-2162 | B35: Grandview Portfolio LLC | C35: =Account_Routing!D35 | D35: =Account_Routing!U35 | E35: =COUNTIF(Src_LossRun!$C$2:$C$43,A35) | F35: =SUMIFS(Src_LossRun!$I$2:$I$43,Src_LossRun!$C$2:$C$43,A35) | G35: =F35-H35 | H35: =SUMIFS(Src_LossRun!$J$2:$J$43,Src_LossRun!$C$2:$C$43,A35) | I35: =H35/C35 | J35: =(I35-D35)*100 | K35: =IF(ABS(J35)>5,"Yes","No") | L35: =Account_Routing!W35 | M35: =IF(I35>=Executive_Summary!$C$8,"Decline (LR >= 70%)",IF(I35>=Executive_Summary!$C$9,"Refer (LR 45%-70%)",IF(L35>=Executive_Summary!$C$10,"Refer (single location >= $250k)","Clear"))) | N35: =I35 | O35: =Account_Routing!AB35 | P35: Refer on two Section 3 triggers: recomputed LR in the 45%-70% band and HAB-2162-C incurred over $250,000; list ratio of 31.8% masked both.
A36: GR-2195 | B36: Humboldt Yard Apts LLC | C36: =Account_Routing!D36 | D36: =Account_Routing!U36 | E36: =COUNTIF(Src_LossRun!$C$2:$C$43,A36) | F36: =SUMIFS(Src_LossRun!$I$2:$I$43,Src_LossRun!$C$2:$C$43,A36) | G36: =F36-H36 | H36: =SUMIFS(Src_LossRun!$J$2:$J$43,Src_LossRun!$C$2:$C$43,A36) | I36: =H36/C36 | J36: =(I36-D36)*100 | K36: =IF(ABS(J36)>5,"Yes","No") | L36: =Account_Routing!W36 | M36: =IF(I36>=Executive_Summary!$C$8,"Decline (LR >= 70%)",IF(I36>=Executive_Summary!$C$9,"Refer (LR 45%-70%)",IF(L36>=Executive_Summary!$C$10,"Refer (single location >= $250k)","Clear"))) | N36: =I36 | O36: =Account_Routing!AB36 | P36: Decline: recomputed LR is more than 4x the account-list figure; list ratio would have understated the account (48.2% would only have been Refer).
A37: GR-2200 | B37: Indiana Ave Partners LLC | C37: =Account_Routing!D37 | D37: =Account_Routing!U37 | E37: =COUNTIF(Src_LossRun!$C$2:$C$43,A37) | F37: =SUMIFS(Src_LossRun!$I$2:$I$43,Src_LossRun!$C$2:$C$43,A37) | G37: =F37-H37 | H37: =SUMIFS(Src_LossRun!$J$2:$J$43,Src_LossRun!$C$2:$C$43,A37) | I37: =H37/C37 | J37: =(I37-D37)*100 | K37: =IF(ABS(J37)>5,"Yes","No") | L37: =Account_Routing!W37 | M37: =IF(I37>=Executive_Summary!$C$8,"Decline (LR >= 70%)",IF(I37>=Executive_Summary!$C$9,"Refer (LR 45%-70%)",IF(L37>=Executive_Summary!$C$10,"Refer (single location >= $250k)","Clear"))) | N37: =I37 | O37: =Account_Routing!AB37 | P37: =IF(K37="Yes","List ratio is stale vs loss run; recomputed ratio used per Section 1 item 2. No Section 3 trigger.","Within 5 points of list; recomputed ratio used. No Section 3 trigger.")
A39: Method: recomputed LR = SUM(paid_amount + reserved_amount, all locations on the account, cat_code blank) / expiring_premium (granite_ridge_routing_notes.txt Section 3; loss run governs per Section 1 item 2). Section 7 requires recomputed ratios wherever list and loss run differ by more than 5 points; all 36 accounts are shown for completeness.

Sheet Rules_Citations
A1: rule_topic | B1: section | C1: routing_action | D1: how applied in this workbook | E1: accounts triggered | F1: source_file
A2: Source hierarchy: loss run governs loss history; location schedule governs TIV, units, subsidized, vacancy, inspections, pool; account list is summary only | B2: Section 1 | C2: Recompute from detail files; do not quote on account-level figures alone | D2: All accounts recomputed from Src_LossRun and Src_Locations | E2: =COUNTA(Account_Routing!A2:A37) | F2: granite_ridge_routing_notes.txt
A3: Loss ratio Decline threshold (>= 70%) | B3: Section 3 | C3: Decline | D3: Recomputed attritional LR = (paid + reserved, cat blank) / expiring_premium | E3: =COUNTIF(Account_Routing!V2:V37,">="&Executive_Summary!C8) | F3: granite_ridge_routing_notes.txt
A4: Loss ratio Refer band (45% to < 70%) | B4: Section 3 | C4: Refer | D4: Same recomputation | E4: =COUNTIFS(Account_Routing!V2:V37,">="&Executive_Summary!C9,Account_Routing!V2:V37,"<"&Executive_Summary!C8) | F4: granite_ridge_routing_notes.txt
A5: Single-location incurred >= $250,000 | B5: Section 3 | C5: Refer | D5: Per-location attritional incurred from Src_Locations column Q | E5: =COUNTIF(Account_Routing!W2:W37,">="&Executive_Summary!C10) | F5: granite_ridge_routing_notes.txt
A6: Unit count variance > 5% | B6: Section 4 | C6: Refer | D6: ABS(list - schedule sum) / list unit_count | E6: =COUNTIF(Account_Routing!I2:I37,">"&Executive_Summary!C11) | F6: granite_ridge_routing_notes.txt
A7: TIV variance > 3% | B7: Section 4 | C7: Refer | D7: ABS(list - schedule sum) / list account_tiv | E7: =COUNTIF(Account_Routing!L2:L37,">"&Executive_Summary!C12) | F7: granite_ridge_routing_notes.txt
A8: Life-safety inspection lapse (> 30 days before 10/1/2025, no renewed certificate) | B8: Section 5 | C8: Refer | D8: Sprinkler or fire alarm date before 2025-09-01; no certificates in package | E8: =COUNTIF(Account_Routing!P2:P37,">0") | F8: granite_ridge_routing_notes.txt
A9: Pool liability flag pending_fence_po | B9: Section 5 | C9: Refer until completion evidence uploaded | D9: Schedule pool_liability_flag | E9: =COUNTIF(Account_Routing!Q2:Q37,">0") | F9: granite_ridge_routing_notes.txt
A10: Subsidized housing (subsidized_unit_count > 0) regardless of list flag | B10: Section 6 | C10: Refer; endorsement documentation (queue GRP-SUB-HAB) | D10: Schedule subsidized_unit_count | E10: =COUNTIF(Account_Routing!N2:N37,">0") | F10: granite_ridge_routing_notes.txt
A11: Vacancy_flag = Y and broker_confirmation = no | B11: Section 6 | C11: Ask Broker (queue GRP-BRK-UPD) | D11: Schedule vacancy_flag and broker_confirmation | E11: =COUNTIF(Account_Routing!S2:S37,">0") | F11: granite_ridge_routing_notes.txt
A12: Full-occupancy summary with unexplained vacancy Y (no documented turnover exception) | B12: Section 6 | C12: Refer | D12: Not triggered: only vacancy row with broker_confirmation = yes is HAB-2047-B on a 94.0% occupancy account (see Decision_Notes note 3) | E12: 0 | F12: granite_ridge_routing_notes.txt
A13: Prior disposition / renewal_ready_flag are informational | B13: Section 8 | C13: Do not override triggers | D13: 35 Quoted + 1 Renewal Ready on list; all flagged Y | E13: =COUNTIFS(Account_Routing!F2:F37,"Y",Account_Routing!AB2:AB37,"<>Quote") | F13: granite_ridge_routing_notes.txt
A14: Catastrophe-coded rows excluded from Section 3 thresholds by default | B14: Section 9 | C14: Exclude; track separately | D14: GR-2071 CAT-2408 excluded | E14: =COUNTIF(Src_LossRun!$H$2:$H$43,"CAT*") | F14: granite_ridge_routing_notes.txt
A15: Student housing (Campus Edge Housing Co.) appetite note; GRP-APPETITE review before bind | B15: Section 10 | C15: Appetite note on Location_Exceptions; do not assume clearance | D15: GR-2007 and GR-2065 routed Refer (judgment) | E15: =SUM(Account_Routing!X2:X37) | F15: granite_ridge_routing_notes.txt
A16: Documentation: all 36 accounts listed; rationale citing section and source file on every non-Quote row; recomputed ratios where list differs > 5 pts | B16: Section 7 | C16: Documentation | D16: Account_Routing, Location_Exceptions, Loss_Reconciliation | E16: =COUNTA(Account_Routing!A2:A37) | F16: granite_ridge_routing_notes.txt
A18: "Accounts triggered" counts accounts (or rows for the cat-code line) that meet the trigger; an account may meet several triggers.

Sheet Decision_Notes
A1: # | B1: Topic | C1: What happened | D1: Why it matters | E1: Source / rule used (granite_ridge_routing_notes.txt) | F1: Effect on disposition
A2: 1 | B2: Account list loss ratios are stale | C2: For 30 of 36 accounts the list loss ratio differs from the recomputed loss-run ratio by more than 5 points, in both directions (see Loss_Reconciliation column K). | D2: The list ratio cannot be used for routing. | E2: Section 1 item 2 (loss run governs); Section 3 formula; Section 7 (show recomputed ratios where difference > 5 points). | F2: Routing uses recomputed ratios only. Changed the outcome for GR-2195 (Decline) and GR-2162 (Refer).
A3: 2 | B3: GR-2195 Humboldt Yard: Decline | C3: Four loss rows total $142,100 incurred against $48,620 premium = 292.3%. Account list showed 48.2%. | D3: A 48.2% list ratio would only be a Refer; actual ratio is more than 4x the decline threshold. | E3: Section 3: Decline if recomputed LR >= 70%. | F3: Decline.
A4: 3 | B4: GR-2047 Quincy Street: vacancy treated as documented (judgment) | C4: HAB-2047-B has vacancy_flag = Y with broker_confirmation = yes; account occupancy is 94.0%. | D4: Ask Broker needs broker_confirmation = no. The Refer vacancy rule needs both full-occupancy occupancy and no documented turnover exception. No numeric definition of "full occupancy" exists in the notes, and no separate broker file is in the package; broker_confirmation = yes is the only documentation available. I did not invent a threshold. | E4: Section 6 (last two sentences); Section 1 item 3. | F4: Quote. If the desk requires a separate turnover-exception document, this account moves to Refer.
A5: 4 | B5: Campus Edge accounts GR-2007 and GR-2065: routed Refer (judgment) | C5: Both accounts have named insured Campus Edge Housing Co. with no vacancy flag and otherwise clean loss/location detail. | D5: Section 10 requires an appetite note stating GRP-APPETITE review must be submitted before bind. A mandatory pre-bind review fits the Refer definition (underwriter review before bind) and cannot be Quote, which requires no mandatory trigger. No CUO clearance memo is in the file package, so clearance is not assumed. | E5: Section 10; Section 2 (Refer and Quote definitions). | F5: Refer for both accounts. Location_Exceptions carries the Section 10 note for each.
A6: 5 | B6: GR-2071 Buckeye Garden: cat loss excluded | C6: CAT-2408 wind loss of $284,600 on HAB-2071-A is cat-coded. Attritional incurred is $4,796.53 (9.6%). | D6: Including the cat loss would trigger both a Decline-level ratio and a single-location Refer. | E6: Section 9 (default exclusion for Section 3 thresholds). CUO memo GRP-CAT-2025-03 is not in the file package. | F6: Quote. Reverses if the CUO confirms memo GRP-CAT-2025-03 applies.
A7: 6 | B7: Inspection lapse cutoff | C7: Batch effective date is October 1, 2025 (Section 5), so a lapse means an inspection dated before 2025-09-01. Only HAB-2089-A (both sprinkler and fire alarm dated 2025-04-02, 182 days) fails; every other date is 2025-09-03 or later (28 days or fewer). | D7: No renewed certificate is in the package, so the grace exception cannot be applied. | E7: Section 5. | F7: GR-2089 Refer.
A8: 7 | B8: GR-2113 Fulton Market: unit and TIV variance | C8: List 142 units and $11,840,000 TIV vs schedule 150 units and $12,810,880 (variance 8 units = 5.63%; $970,880 = 8.20%). All other accounts are within 1.5% TIV and 0% units. | D8: Both variances exceed tolerance; the schedule governs. | E8: Section 4; Section 1 item 3. | F8: Refer.
A9: 8 | B9: GR-2162 Grandview: two Section 3 triggers | C9: Recomputed LR is 67.5% ($265,360 / $392,850) and HAB-2162-C alone carries $260,120 incurred. | D9: Either trigger alone forces Refer; list ratio of 31.8% hid both. 67.5% is below the 70% decline threshold. | E9: Section 3. | F9: Refer.
A10: 9 | B10: Subsidized housing | C10: HAB-2053-A (24 units), HAB-2068-B (18) and HAB-2092-A (22) carry subsidized units. The list subsidized_housing_flag is already Y for all three accounts and N for every account with no subsidized units, so there is no flag mismatch. | D10: Refer applies even where the list flag is N; here it agrees with the schedule. | E10: Section 6; queue GRP-SUB-HAB. | F10: GR-2053, GR-2068, GR-2092 Refer.
